Workbook

Sheet README
A1: theCreative.exchange — 5-year model v2: two tracks, every revenue source, three scenarios
A2: Built 2026-09-30 as a fresh look at the 2026-08-28 model (financial-model-3yr.xlsx). Same prices and take rates as claims.md and the plan; new revenue lines are marked PROPOSED.
A4: HOW TO USE
A5: Blue text = an input you can change. Black = formula. Green = a link to another sheet. Yellow fill = the assumptions that most change the answer.
A6: The yellow cell on the Inputs sheet (Scenario switch) drives everything: 1 = Conservative, 2 = Base, 3 = Fundable. Every other sheet follows it.
A7: Sheets: Inputs (prices, take rates, scenario drivers) · Garden (track A: the house community) · Exchange (track B: partner communities and B2B) · Combined (revenue by source, costs, cash) · Market (who is out there, and what share the model assumes) · Use of Funds (the raise by function, runway by raise size) · Sensitivity · Comps.
A9: WHAT THE FRESH LOOK SAYS
A10: 1. The old model had one engine: 10% of small flows plus $10 seats, San Diego only. That is a $50–150k/year business at best, and it never pays anyone. The estimates were not too conservative; the model was too narrow.
A11: 2. Fundability comes from four things the old model left out: (a) B2B seats — churches and organizations buying 10–100 seats a year in one charge; (b) subscriptions from hosts, organizations and gig posters, the SaaS line Skool and Circle live on; (c) a national footprint through the partner networks already mapped (ACFW, Word Weavers, Realm Makers, NCVA, Hope*Writers-sized communities); (d) event ticketing and program-administration fees on flows the platform already carries.
A12: 3. The Garden alone (track A) is a healthy community business that funds real grants but not a company. The Exchange (track B) is where the company's revenue comes from. Model them separately; pitch them together.
A13: 4. Results (2026-09-30: franchise metros as explicit drivers, a Base team of four, founder pay inside the functions). Base revenue $36k / $146k / $461k / $1.06M / $2.11M; EBITDA -$192k / -$313k / -$318k / -$3k / +$672k, so breakeven in year four and about $826k of cumulative capital at the low point. Fundable revenue $80k / $363k / $1.38M / $3.89M / $9.29M with 40 metros and a team of 18, EBITDA positive in year four. Conservative: $17k growing to $313k with 5 metros, not profitable in five years. Costs, EBITDA and cash are on the Combined sheet; docs/funding/cfo-memo-ask-and-spend.md carries the discussion.
A14: 4b. The ask (Use of Funds sheet): an 18-month window at Base, what it spends by function, what it earns, and the net cash need; runway by raise size below it. Founder pay in Base is conditional on a first close of at least $150k and starts the month after it on a ramp ($4k/mo, then $5.5k/mo; $51k each in Y1, $78k in Y2, then $105k / $125k / $140k). Part-time marketing and launch help from month 1 (0.25 FTE, 0.5 in Y2) and part-time coordinator hours; the first full-time employee (community & partnerships lead) starts at month 18; the team is four people from Y3 (2.25 / 3 / 4 / 4 / 4 FTE including founders; Headcount plan on the Use of Funds sheet), with contractors and outsourced bookkeeping instead of engineering, support and ops hires; franchise metros (5 / 20 / 40 by Y5 across the scenarios) run themselves.
... A19: PROPOSED LINES (decide before you show this to anyone): host/org plan at $50/mo (already in the business model doc, not built), partner plan for gig posters at $79/mo (new), 5% fee on event tickets (new; events are built), $25/mo Pro seat (mentioned in the business model doc). None of these is in claims.md yet.

Sheet Inputs
A1: Inputs — prices, take rates, costs, scenario drivers
A2: Blue = edit. Sources in column H. Prices verified against claims.md v1 (2026-09-18) and the plan v0.6 unless marked PROPOSED.
A4: A · Prices and take rates
A5: Seat (membership), $/month | B5: 10 | H5: claims.md: Membership is $10 a month
A6: Pro seat, $/month (PROPOSED) | B6: 25 | H6: Business Model doc: '$25 runs several projects at once'. Not in claims.md.
A7: Annual billing discount (10 months for 12) | B7: 0.1667 | H7: Two months free on annual; Business Model §03
A8: Garden dues: share to the grant program | B8: 0.5 | H8: claims.md: 'Half of your membership funds grants for other creatives'
A9: Garden dues: share kept by the platform (house community) | B9: 0.5 | H9: claims.md 'dues, other half': today the code sends all of it to the platform; Garden community work is paid hourly from it (cost line below)
A10: Partner-community dues: platform take | B10: 0.1 | H10: Plan v0.6: 10% platform; 90% belongs to the community
A11: Backings: platform take | B11: 0.1 | H11: claims.md: $100 → $90 to the creative (5% above $1,000 ignored here)
A12: Classes and premium: platform take | B12: 0.1 | H12: claims.md host split: hosts keep 90%
A13: Gifts to a nonprofit-run program: platform fee | B13: 0.05 | H13: Business Model §02: 5% platform, 5% program administration (AP), ~87–90% to creatives
A14: Event tickets: platform fee (PROPOSED) | B14: 0.05 | H14: Events and ticketing are built; Eventbrite charges 3.7% + $1.79. Not in claims.md.
A15: Host / organization plan, $/month (PROPOSED) | B15: 50 | H15: Business Model §01 'Leader tier': run funding programs, contests, cohorts. Not built.
A16: Partner plan for gig posters, $/month (PROPOSED) | B16: 79 | H16: Churches, businesses and nonprofits posting paid work. Comparable: job boards $99–$299/post.
... A28: Founder market salary, $/year (each) | B28: 175000 | H28: Business Model §05: $175–240k for the seat; used for the founder-pay gap
A29: Scenario switch: 1 = Conservative · 2 = Base · 3 = Fundable | B29: 2
A31: B · Scenario drivers (Conservative / Base / Fundable; the Active row follows the switch)
A32: Driver | B32: Scenario | C32: Y1 (Nov26–Oct27) | D32: Y2 | E32: Y3 | F32: Y4 | G32: Y5 | H32: Note
A33: TRACK A — THE GARDEN (house community: San Diego first, then Garden chapters in other metros)
A34: Paying individual members, average active | B34: Conservative | C34: 100 | D34: 250 | E34: 450 | F34: 650 | G34: 850 | H34: Old model M: 400/1,500/4,500 total members; here the Garden alone. Market!B-column shows what share of San Diego creatives this is.
B35: Base | C35: 150 | D35: 400 | E35: 800 | F35: 1200 | G35: 1600
B36: Fundable | C36: 250 | D36: 700 | E36: 1500 | F36: 2500 | G36: 3500
B37: Active | C37: =CHOOSE(Inputs!$B$29,C34,C35,C36) -> 150 | D37: =CHOOSE(Inputs!$B$29,D34,D35,D36) -> 400 | E37: =CHOOSE(Inputs!$B$29,E34,E35,E36) -> 800 | F37: =CHOOSE(Inputs!$B$29,F34,F35,F36) -> 1200 | G37: =CHOOSE(Inputs!$B$29,G34,G35,G36) -> 1600
A39: Church-covered seats, average active | B39: Conservative | C39: 20 | D39: 60 | E39: 120 | F39: 200 | G39: 300 | H39: Ten seats per church; Base Y3 = 50 churches. San Diego County has about 1,555 reporting congregations (Market sheet).
B40: Base | C40: 50 | D40: 200 | E40: 500 | F40: 900 | G40: 1400
B41: Fundable | C41: 100 | D41: 500 | E41: 1500 | F41: 3000 | G41: 5000
B42: Active | C42: =CHOOSE(Inputs!$B$29,C39,C40,C41) -> 50 | D42: =CHOOSE(Inputs!$B$29,D39,D40,D41) -> 200 | E42: =CHOOSE(Inputs!$B$29,E39,E40,E41) -> 500 | F42: =CHOOSE(Inputs!$B$29,F39,F40,F41) -> 900 | G42: =CHOOSE(Inputs!$B$29,G39,G40,G41) -> 1400
A44: Share of individual members on the Pro seat | B44: Conservative | C44: 0 | D44: 0.05 | E44: 0.08 | F44: 0.1 | G44: 0.1 | H44: PROPOSED $25 seat
B45: Base | C45: 0.05 | D45: 0.1 | E45: 0.15 | F45: 0.2 | G45: 0.2
B46: Fundable | C46: 0.1 | D46: 0.15 | E46: 0.2 | F46: 0.25 | G46: 0.25
B47: Active | C47: =CHOOSE(Inputs!$B$29,C44,C45,C46) -> 0.05 | D47: =CHOOSE(Inputs!$B$29,D44,D45,D46) -> 0.1 | E47: =CHOOSE(Inputs!$B$29,E44,E45,E46) -> 0.15 | F47: =CHOOSE(Inputs!$B$29,F44,F45,F46) -> 0.2 | G47: =CHOOSE(Inputs!$B$29,G44,G45,G46) -> 0.2
A49: Backing GMV per paying member per year, $ | B49: Conservative | C49: 40 | D49: 50 | E49: 60 | F49: 70 | G49: 80 | H49: Old model: $60–300 'other money moved'. Patreon average pledge is ~$5–10/mo per patron (Comps).
B50: Base | C50: 75 | D50: 100 | E50: 125 | F50: 150 | G50: 175
B51: Fundable | C51: 100 | D51: 150 | E51: 200 | F51: 250 | G51: 300
B52: Active | C52: =CHOOSE(Inputs!$B$29,C49,C50,C51) -> 75 | D52: =CHOOSE(Inputs!$B$29,D49,D50,D51) -> 100 | E52: =CHOOSE(Inputs!$B$29,E49,E50,E51) -> 125 | F52: =CHOOSE(Inputs!$B$29,F49,F50,F51) -> 150 | G52: =CHOOSE(Inputs!$B$29,G49,G50,G51) -> 175
A54: Class and premium GMV per paying member per year, $ | B54: Conservative | C54: 30 | D54: 40 | E54: 50 | F54: 60 | G54: 70 | H54: A $120 cohort and a $5/mo premium reach $140/yr
B55: Base | C55: 60 | D55: 80 | E55: 100 | F55: 120 | G55: 140
B56: Fundable | C56: 80 | D56: 110 | E56: 140 | F56: 170 | G56: 200
B57: Active | C57: =CHOOSE(Inputs!$B$29,C54,C55,C56) -> 60 | D57: =CHOOSE(Inputs!$B$29,D54,D55,D56) -> 80 | E57: =CHOOSE(Inputs!$B$29,E54,E55,E56) -> 100 | F57: =CHOOSE(Inputs!$B$29,F54,F55,F56) -> 120 | G57: =CHOOSE(Inputs!$B$29,G54,G55,G56) -> 140
...

Sheet Garden
A1: Track A — The Garden (house community)
A2: =IF(Inputs!$B$29=1,"Scenario: Conservative",IF(Inputs!$B$29=2,"Scenario: Base","Scenario: Fundable")) -> Scenario: Base
B3: Y1 (Nov26–Oct27) | C3: Y2 | D3: Y3 | E3: Y4 | F3: Y5 | G3: How
A5: Drivers (green = from Inputs, active scenario)
A6: Paying individual members (avg) | B6: =Inputs!$C$37 -> 150 | C6: =Inputs!$D$37 -> 400 | D6: =Inputs!$E$37 -> 800 | E6: =Inputs!$F$37 -> 1200 | F6: =Inputs!$G$37 -> 1600
A7: Church-covered seats (avg) | B7: =Inputs!$C$42 -> 50 | C7: =Inputs!$D$42 -> 200 | D7: =Inputs!$E$42 -> 500 | E7: =Inputs!$F$42 -> 900 | F7: =Inputs!$G$42 -> 1400
A8: Share on Pro seat | B8: =Inputs!$C$47 -> 0.05 | C8: =Inputs!$D$47 -> 0.1 | D8: =Inputs!$E$47 -> 0.15 | E8: =Inputs!$F$47 -> 0.2 | F8: =Inputs!$G$47 -> 0.2
A9: Backing GMV per paying member, $/yr | B9: =Inputs!$C$52 -> 75 | C9: =Inputs!$D$52 -> 100 | D9: =Inputs!$E$52 -> 125 | E9: =Inputs!$F$52 -> 150 | F9: =Inputs!$G$52 -> 175
A10: Class GMV per paying member, $/yr | B10: =Inputs!$C$57 -> 60 | C10: =Inputs!$D$57 -> 80 | D10: =Inputs!$E$57 -> 100 | E10: =Inputs!$F$57 -> 120 | F10: =Inputs!$G$57 -> 140
A11: Gifts to the program, $/yr | B11: =Inputs!$C$62 -> 25000 | C11: =Inputs!$D$62 -> 60000 | D11: =Inputs!$E$62 -> 120000 | E11: =Inputs!$F$62 -> 200000 | F11: =Inputs!$G$62 -> 300000
A12: Event ticket GMV, $/yr | B12: =Inputs!$C$67 -> 15000 | C12: =Inputs!$D$67 -> 30000 | D12: =Inputs!$E$67 -> 50000 | E12: =Inputs!$F$67 -> 75000 | F12: =Inputs!$G$67 -> 100000
A13: Sponsorships, count | B13: =Inputs!$C$72 -> 2 | C13: =Inputs!$D$72 -> 4 | D13: =Inputs!$E$72 -> 8 | E13: =Inputs!$F$72 -> 12 | F13: =Inputs!$G$72 -> 16
A14: Community engagement, hrs/wk | B14: =Inputs!$C$77 -> 10 | C14: =Inputs!$D$77 -> 15 | D14: =Inputs!$E$77 -> 10 | E14: =Inputs!$F$77 -> 0 | F14: =Inputs!$G$77 -> 0
A16: Money moved (GMV)
A17: Individual dues GMV | B17: =B6*12*(Inputs!$B$5*(1-B8)+Inputs!$B$6*B8)*(1-Inputs!$B$7*(1-Inputs!$B$21)) -> 18059.742 | C17: =C6*12*(Inputs!$B$5*(1-C8)+Inputs!$B$6*C8)*(1-Inputs!$B$7*(1-Inputs!$B$21)) -> 51519.264 | D17: =D6*12*(Inputs!$B$5*(1-D8)+Inputs!$B$6*D8)*(1-Inputs!$B$7*(1-Inputs!$B$21)) -> 109758.43 | E17: =E6*12*(Inputs!$B$5*(1-E8)+Inputs!$B$6*E8)*(1-Inputs!$B$7*(1-Inputs!$B$21)) -> 174717.5 | F17: =F6*12*(Inputs!$B$5*(1-F8)+Inputs!$B$6*F8)*(1-Inputs!$B$7*(1-Inputs!$B$21)) -> 232956.67 | G17: members × 12 × blended seat price, annual discount on the annual share
A18: Church seat-pack GMV | B18: =B7*Inputs!$B$17 -> 5000 | C18: =C7*Inputs!$B$17 -> 20000 | D18: =D7*Inputs!$B$17 -> 50000 | E18: =E7*Inputs!$B$17 -> 90000 | F18: =F7*Inputs!$B$17 -> 140000 | G18: seats × $100/yr, one charge per church
A19: Backings GMV | B19: =(B6+B7)*B9 -> 15000 | C19: =(C6+C7)*C9 -> 60000 | D19: =(D6+D7)*D9 -> 162500 | E19: =(E6+E7)*E9 -> 315000 | F19: =(F6+F7)*F9 -> 525000 | G19: all paying and covered members × backing per member
A20: Classes and premium GMV | B20: =(B6+B7)*B10 -> 12000 | C20: =(C6+C7)*C10 -> 48000 | D20: =(D6+D7)*D10 -> 130000 | E20: =(E6+E7)*E10 -> 252000 | F20: =(F6+F7)*F10 -> 420000
A21: Gifts to the program (through AP) | B21: =B11 -> 25000 | C21: =C11 -> 60000 | D21: =D11 -> 120000 | E21: =E11 -> 200000 | F21: =F11 -> 300000
A22: Event tickets GMV | B22: =B12 -> 15000 | C22: =C12 -> 30000 | D22: =D12 -> 50000 | E22: =E12 -> 75000 | F22: =F12 -> 100000
A23: Sponsorships | B23: =B13*Inputs!$B$18 -> 10000 | C23: =C13*Inputs!$B$18 -> 20000 | D23: =D13*Inputs!$B$18 -> 40000 | E23: =E13*Inputs!$B$18 -> 60000 | F23: =F13*Inputs!$B$18 -> 80000
A24: TOTAL MONEY MOVED — Garden | B24: =SUM(B17:B23) -> 100059.74 | C24: =SUM(C17:C23) -> 289519.26 | D24: =SUM(D17:D23) -> 662258.43 | E24: =SUM(E17:E23) -> 1166717.5 | F24: =SUM(F17:F23) -> 1797956.7
A26: Platform revenue from the Garden
A27: Dues kept by the platform (house share) | B27: =(B17+B18)*Inputs!$B$9 -> 11529.871 | C27: =(C17+C18)*Inputs!$B$9 -> 35759.632 | D27: =(D17+D18)*Inputs!$B$9 -> 79879.216 | E27: =(E17+E18)*Inputs!$B$9 -> 132358.75 | F27: =(F17+F18)*Inputs!$B$9 -> 186478.34 | G27: the other half funds the program
A28: Backing fees | B28: =B19*Inputs!$B$11 -> 1500 | C28: =C19*Inputs!$B$11 -> 6000 | D28: =D19*Inputs!$B$11 -> 16250 | E28: =E19*Inputs!$B$11 -> 31500 | F28: =F19*Inputs!$B$11 -> 52500
A29: Class fees | B29: =B20*Inputs!$B$12 -> 1200 | C29: =C20*Inputs!$B$12 -> 4800 | D29: =D20*Inputs!$B$12 -> 13000 | E29: =E20*Inputs!$B$12 -> 25200 | F29: =F20*Inputs!$B$12 -> 42000
A30: Program platform fee (5% of gifts) | B30: =B21*Inputs!$B$13 -> 1250 | C30: =C21*Inputs!$B$13 -> 3000 | D30: =D21*Inputs!$B$13 -> 6000 | E30: =E21*Inputs!$B$13 -> 10000 | F30: =F21*Inputs!$B$13 -> 15000
A31: Event ticket fees (PROPOSED) | B31: =B22*Inputs!$B$14 -> 750 | C31: =C22*Inputs!$B$14 -> 1500 | D31: =D22*Inputs!$B$14 -> 2500 | E31: =E22*Inputs!$B$14 -> 3750 | F31: =F22*Inputs!$B$14 -> 5000
A32: Sponsorships (100% company) | B32: =B23 -> 10000 | C32: =C23 -> 20000 | D32: =D23 -> 40000 | E32: =E23 -> 60000 | F32: =F23 -> 80000
A33: GARDEN PLATFORM REVENUE | B33: =SUM(B27:B32) -> 26229.871 | C33: =SUM(C27:C32) -> 71059.632 | D33: =SUM(D27:D32) -> 157629.22 | E33: =SUM(E27:E32) -> 262808.75 | F33: =SUM(F27:F32) -> 380978.34
A35: What the program gets (not company revenue)
A36: Half of dues to the program | B36: =(B17+B18)*Inputs!$B$8 -> 11529.871 | C36: =(C17+C18)*Inputs!$B$8 -> 35759.632 | D36: =(D17+D18)*Inputs!$B$8 -> 79879.216 | E36: =(E17+E18)*Inputs!$B$8 -> 132358.75 | F36: =(F17+F18)*Inputs!$B$8 -> 186478.34
A37: Gifts net of fees (~90%) | B37: =B21*(1-Inputs!$B$13*2) -> 22500 | C37: =C21*(1-Inputs!$B$13*2) -> 54000 | D37: =D21*(1-Inputs!$B$13*2) -> 108000 | E37: =E21*(1-Inputs!$B$13*2) -> 180000 | F37: =F21*(1-Inputs!$B$13*2) -> 270000
A38: PROGRAM DOLLARS TO CREATIVES (fellowships, commissions, seats) | B38: =B36+B37 -> 34029.871 | C38: =C36+C37 -> 89759.632 | D38: =D36+D37 -> 187879.22 | E38: =E36+E37 -> 312358.75 | F38: =F36+F37 -> 456478.34 | G38: the impact number: money the program can award
A39: Creatives reached at ~$800 average award | B39: =ROUND(B38/800,0) -> 43 | C39: =ROUND(C38/800,0) -> 112 | D39: =ROUND(D38/800,0) -> 235 | E39: =ROUND(E38/800,0) -> 390 | F39: =ROUND(F38/800,0) -> 571 | G39: Business Model §04 mix of micro-grants, tuition, project grants, fellowships
A41: Garden direct costs
A42: Community engagement (hourly) | B42: =B14*52*Inputs!$C$210 -> 15600 | C42: =C14*52*Inputs!$D$210 -> 23400 | D42: =D14*52*Inputs!$E$210 -> 16120 | E42: =E14*52*Inputs!$F$210 -> 0 | F42: =F14*52*Inputs!$G$210 -> 0
A43: Card processing absorbed on dues (monthly share) | B43: =B17*Inputs!$B$21*(Inputs!$B$19+Inputs!$B$20/Inputs!$B$5)+B17*(1-Inputs!$B$21)*Inputs!$B$19 -> 848.80787 | C43: =C17*Inputs!$B$21*(Inputs!$B$19+Inputs!$B$20/Inputs!$B$5)+C17*(1-Inputs!$B$21)*Inputs!$B$19 -> 2421.4054 | D43: =D17*Inputs!$B$21*(Inputs!$B$19+Inputs!$B$20/Inputs!$B$5)+D17*(1-Inputs!$B$21)*Inputs!$B$19 -> 5158.6463 | E43: =E17*Inputs!$B$21*(Inputs!$B$19+Inputs!$B$20/Inputs!$B$5)+E17*(1-Inputs!$B$21)*Inputs!$B$19 -> 8211.7227 | F43: =F17*Inputs!$B$21*(Inputs!$B$19+Inputs!$B$20/Inputs!$B$5)+F17*(1-Inputs!$B$21)*Inputs!$B$19 -> 10948.964 | G43: monthly $10 charges cost ~5.9%; annual ~2.9%
A44: Payout costs (backings, classes) | B44: =(B19*(1-Inputs!$B$11)+B20*(1-Inputs!$B$12))*Inputs!$B$22 -> 243 | C44: =(C19*(1-Inputs!$B$11)+C20*(1-Inputs!$B$12))*Inputs!$B$22 -> 972 | D44: =(D19*(1-Inputs!$B$11)+D20*(1-Inputs!$B$12))*Inputs!$B$22 -> 2632.5 | E44: =(E19*(1-Inputs!$B$11)+E20*(1-Inputs!$B$12))*Inputs!$B$22 -> 5103 | F44: =(F19*(1-Inputs!$B$11)+F20*(1-Inputs!$B$12))*Inputs!$B$22 -> 8505
A45: GARDEN TRACK CONTRIBUTION | B45: =B33-SUM(B42:B44) -> 9538.0631 | C45: =C33-SUM(C42:C44) -> 44266.227 | D45: =D33-SUM(D42:D44) -> 133718.07 | E45: =E33-SUM(E42:E44) -> 249494.03 | F45: =F33-SUM(F42:F44) -> 361524.37
...

Sheet Exchange
A1: Track B — The Exchange (partner communities, hosts, B2B)
A2: =IF(Inputs!$B$29=1,"Scenario: Conservative",IF(Inputs!$B$29=2,"Scenario: Base","Scenario: Fundable")) -> Scenario: Base
B3: Y1 (Nov26–Oct27) | C3: Y2 | D3: Y3 | E3: Y4 | F3: Y5 | G3: How
A5: Drivers (green = from Inputs, active scenario)
A6: Partner communities (avg active) | B6: =Inputs!$C$83 -> 4 | C6: =Inputs!$D$83 -> 12 | D6: =Inputs!$E$83 -> 30 | E6: =Inputs!$F$83 -> 60 | F6: =Inputs!$G$83 -> 100
A7: Paying members per community | B7: =Inputs!$C$88 -> 40 | C7: =Inputs!$D$88 -> 60 | D7: =Inputs!$E$88 -> 80 | E7: =Inputs!$F$88 -> 100 | F7: =Inputs!$G$88 -> 120
A8: Org seat packs, seats active | B8: =Inputs!$C$93 -> 0 | C8: =Inputs!$D$93 -> 300 | D8: =Inputs!$E$93 -> 2000 | E8: =Inputs!$F$93 -> 3500 | F8: =Inputs!$G$93 -> 6000
A9: Class GMV per community, $/yr | B9: =Inputs!$C$98 -> 4000 | C9: =Inputs!$D$98 -> 8000 | D9: =Inputs!$E$98 -> 12000 | E9: =Inputs!$F$98 -> 16000 | F9: =Inputs!$G$98 -> 20000
A10: Backing GMV per paying member, $/yr | B10: =Inputs!$C$103 -> 60 | C10: =Inputs!$D$103 -> 80 | D10: =Inputs!$E$103 -> 100 | E10: =Inputs!$F$103 -> 120 | F10: =Inputs!$G$103 -> 140
A11: Share of communities on host/org plan | B11: =Inputs!$C$108 -> 0.25 | C11: =Inputs!$D$108 -> 0.35 | D11: =Inputs!$E$108 -> 0.45 | E11: =Inputs!$F$108 -> 0.5 | F11: =Inputs!$G$108 -> 0.5
A12: Partner plans (gig posters) | B12: =Inputs!$C$113 -> 5 | C12: =Inputs!$D$113 -> 20 | D12: =Inputs!$E$113 -> 60 | E12: =Inputs!$F$113 -> 150 | F12: =Inputs!$G$113 -> 300
A13: Gifts to partner-run programs, $/yr | B13: =Inputs!$C$118 -> 0 | C13: =Inputs!$D$118 -> 20000 | D13: =Inputs!$E$118 -> 60000 | E13: =Inputs!$F$118 -> 150000 | F13: =Inputs!$G$118 -> 300000
A14: Event ticket GMV, $/yr | B14: =Inputs!$C$123 -> 5000 | C14: =Inputs!$D$123 -> 20000 | D14: =Inputs!$E$123 -> 60000 | E14: =Inputs!$F$123 -> 150000 | F14: =Inputs!$G$123 -> 300000
A15: Sponsorships, count | B15: =Inputs!$C$128 -> 0 | C15: =Inputs!$D$128 -> 2 | D15: =Inputs!$E$128 -> 6 | E15: =Inputs!$F$128 -> 12 | F15: =Inputs!$G$128 -> 20
A16: Franchise metros launched in the year | B16: =Inputs!$C$133 -> 0 | C16: =Inputs!$D$133 -> 2 | D16: =Inputs!$E$133 -> 4 | E16: =Inputs!$F$133 -> 6 | F16: =Inputs!$G$133 -> 8
A17: Cost to launch a metro, $ | B17: =Inputs!$C$138 -> 12000 | C17: =Inputs!$D$138 -> 12000 | D17: =Inputs!$E$138 -> 12000 | E17: =Inputs!$F$138 -> 12000 | F17: =Inputs!$G$138 -> 12000
A18: Cost to support an active metro, $/yr | B18: =Inputs!$C$143 -> 6000 | C18: =Inputs!$D$143 -> 6000 | D18: =Inputs!$E$143 -> 6000 | E18: =Inputs!$F$143 -> 6000 | F18: =Inputs!$G$143 -> 6000
A19: Communities per active metro | B19: =Inputs!$C$148 -> 2 | C19: =Inputs!$D$148 -> 3 | D19: =Inputs!$E$148 -> 4 | E19: =Inputs!$F$148 -> 5 | F19: =Inputs!$G$148 -> 6
A20: Franchise metros active (cumulative, launch year counts) | B20: =B16 -> 0 | C20: =B20+C16 -> 2 | D20: =C20+D16 -> 6 | E20: =D20+E16 -> 12 | F20: =E20+F16 -> 20 | G20: running total of launches
A21: Metro communities (avg active) | B21: =B20*B19 -> 0 | C21: =C20*C19 -> 6 | D21: =D20*D19 -> 24 | E21: =E20*E19 -> 60 | F21: =F20*F19 -> 120 | G21: metros × communities per metro
A22: Partner communities, total (networks + metros) | B22: =B6+B21 -> 4 | C22: =C6+C21 -> 18 | D22: =D6+D21 -> 54 | E22: =E6+E21 -> 120 | F22: =F6+F21 -> 220
A23: Paying members across partner communities | B23: =B22*B7 -> 160 | C23: =C22*C7 -> 1080 | D23: =D22*D7 -> 4320 | E23: =E22*E7 -> 12000 | F23: =F22*F7 -> 26400 | G23: communities × members per community
A25: Money moved (GMV)
A26: Partner-community dues GMV | B26: =B23*12*Inputs!$B$5*(1-Inputs!$B$7*(1-Inputs!$B$21)) -> 17919.744 | C26: =C23*12*Inputs!$B$5*(1-Inputs!$B$7*(1-Inputs!$B$21)) -> 120958.27 | D26: =D23*12*Inputs!$B$5*(1-Inputs!$B$7*(1-Inputs!$B$21)) -> 483833.09 | E26: =E23*12*Inputs!$B$5*(1-Inputs!$B$7*(1-Inputs!$B$21)) -> 1343980.8 | F26: =F23*12*Inputs!$B$5*(1-Inputs!$B$7*(1-Inputs!$B$21)) -> 2956757.8 | G26: members × $10 × 12, annual discount on the annual share
A27: Org seat-pack GMV | B27: =B8*Inputs!$B$17 -> 0 | C27: =C8*Inputs!$B$17 -> 30000 | D27: =D8*Inputs!$B$17 -> 200000 | E27: =E8*Inputs!$B$17 -> 350000 | F27: =F8*Inputs!$B$17 -> 600000
A28: Backings GMV | B28: =(B23+B8)*B10 -> 9600 | C28: =(C23+C8)*C10 -> 110400 | D28: =(D23+D8)*D10 -> 632000 | E28: =(E23+E8)*E10 -> 1860000 | F28: =(F23+F8)*F10 -> 4536000
A29: Classes and premium GMV | B29: =B22*B9 -> 16000 | C29: =C22*C9 -> 144000 | D29: =D22*D9 -> 648000 | E29: =E22*E9 -> 1920000 | F29: =F22*F9 -> 4400000
A30: Gifts to partner-run programs | B30: =B13 -> 0 | C30: =C13 -> 20000 | D30: =D13 -> 60000 | E30: =E13 -> 150000 | F30: =F13 -> 300000
A31: Event tickets GMV | B31: =B14 -> 5000 | C31: =C14 -> 20000 | D31: =D14 -> 60000 | E31: =E14 -> 150000 | F31: =F14 -> 300000
A32: Sponsorships | B32: =B15*Inputs!$B$18 -> 0 | C32: =C15*Inputs!$B$18 -> 10000 | D32: =D15*Inputs!$B$18 -> 30000 | E32: =E15*Inputs!$B$18 -> 60000 | F32: =F15*Inputs!$B$18 -> 100000
A33: Host/org plan subscriptions (PROPOSED) | B33: =B22*B11*Inputs!$B$15*12 -> 600 | C33: =C22*C11*Inputs!$B$15*12 -> 3780 | D33: =D22*D11*Inputs!$B$15*12 -> 14580 | E33: =E22*E11*Inputs!$B$15*12 -> 36000 | F33: =F22*F11*Inputs!$B$15*12 -> 66000
A34: Partner plan subscriptions (PROPOSED) | B34: =B12*Inputs!$B$16*12 -> 4740 | C34: =C12*Inputs!$B$16*12 -> 18960 | D34: =D12*Inputs!$B$16*12 -> 56880 | E34: =E12*Inputs!$B$16*12 -> 142200 | F34: =F12*Inputs!$B$16*12 -> 284400
A35: TOTAL MONEY MOVED — Exchange | B35: =SUM(B26:B34) -> 53859.744 | C35: =SUM(C26:C34) -> 478098.27 | D35: =SUM(D26:D34) -> 2185293.1 | E35: =SUM(E26:E34) -> 6012180.8 | F35: =SUM(F26:F34) -> 13543158
A37: Platform revenue from the Exchange
A38: Dues take (10%) incl. org seats | B38: =(B26+B27)*Inputs!$B$10 -> 1791.9744 | C38: =(C26+C27)*Inputs!$B$10 -> 15095.827 | D38: =(D26+D27)*Inputs!$B$10 -> 68383.309 | E38: =(E26+E27)*Inputs!$B$10 -> 169398.08 | F38: =(F26+F27)*Inputs!$B$10 -> 355675.78
A39: Backing fees | B39: =B28*Inputs!$B$11 -> 960 | C39: =C28*Inputs!$B$11 -> 11040 | D39: =D28*Inputs!$B$11 -> 63200 | E39: =E28*Inputs!$B$11 -> 186000 | F39: =F28*Inputs!$B$11 -> 453600
A40: Class fees | B40: =B29*Inputs!$B$12 -> 1600 | C40: =C29*Inputs!$B$12 -> 14400 | D40: =D29*Inputs!$B$12 -> 64800 | E40: =E29*Inputs!$B$12 -> 192000 | F40: =F29*Inputs!$B$12 -> 440000
A41: Program platform fee (5% of gifts) | B41: =B30*Inputs!$B$13 -> 0 | C41: =C30*Inputs!$B$13 -> 1000 | D41: =D30*Inputs!$B$13 -> 3000 | E41: =E30*Inputs!$B$13 -> 7500 | F41: =F30*Inputs!$B$13 -> 15000
A42: Event ticket fees (PROPOSED) | B42: =B31*Inputs!$B$14 -> 250 | C42: =C31*Inputs!$B$14 -> 1000 | D42: =D31*Inputs!$B$14 -> 3000 | E42: =E31*Inputs!$B$14 -> 7500 | F42: =F31*Inputs!$B$14 -> 15000
A43: Sponsorships (100% company) | B43: =B32 -> 0 | C43: =C32 -> 10000 | D43: =D32 -> 30000 | E43: =E32 -> 60000 | F43: =F32 -> 100000
...

Sheet Combined
A1: Combined — revenue by source, costs, cash
A2: =IF(Inputs!$B$29=1,"Scenario: Conservative",IF(Inputs!$B$29=2,"Scenario: Base","Scenario: Fundable")) -> Scenario: Base
B3: Y1 (Nov26–Oct27) | C3: Y2 | D3: Y3 | E3: Y4 | F3: Y5 | G3: How
A5: Platform revenue by source (both tracks)
A6: Membership dues kept (Garden house share + 10% of partner dues) | B6: =Garden!B27+Exchange!B38 -> 13321.845 | C6: =Garden!C27+Exchange!C38 -> 50855.459 | D6: =Garden!D27+Exchange!D38 -> 148262.52 | E6: =Garden!E27+Exchange!E38 -> 301756.83 | F6: =Garden!F27+Exchange!F38 -> 542154.11
A7: Backing fees (10%) | B7: =Garden!B28+Exchange!B39 -> 2460 | C7: =Garden!C28+Exchange!C39 -> 17040 | D7: =Garden!D28+Exchange!D39 -> 79450 | E7: =Garden!E28+Exchange!E39 -> 217500 | F7: =Garden!F28+Exchange!F39 -> 506100
A8: Class and premium fees (10%) | B8: =Garden!B29+Exchange!B40 -> 2800 | C8: =Garden!C29+Exchange!C40 -> 19200 | D8: =Garden!D29+Exchange!D40 -> 77800 | E8: =Garden!E29+Exchange!E40 -> 217200 | F8: =Garden!F29+Exchange!F40 -> 482000
A9: Program platform fees (5% of gifts) | B9: =Garden!B30+Exchange!B41 -> 1250 | C9: =Garden!C30+Exchange!C41 -> 4000 | D9: =Garden!D30+Exchange!D41 -> 9000 | E9: =Garden!E30+Exchange!E41 -> 17500 | F9: =Garden!F30+Exchange!F41 -> 30000
A10: Event ticket fees (5%, PROPOSED) | B10: =Garden!B31+Exchange!B42 -> 1000 | C10: =Garden!C31+Exchange!C42 -> 2500 | D10: =Garden!D31+Exchange!D42 -> 5500 | E10: =Garden!E31+Exchange!E42 -> 11250 | F10: =Garden!F31+Exchange!F42 -> 20000
A11: Sponsorships | B11: =Garden!B32+Exchange!B43 -> 10000 | C11: =Garden!C32+Exchange!C43 -> 30000 | D11: =Garden!D32+Exchange!D43 -> 70000 | E11: =Garden!E32+Exchange!E43 -> 120000 | F11: =Garden!F32+Exchange!F43 -> 180000
A12: Host/org plans (PROPOSED) | B12: =Exchange!B44 -> 600 | C12: =Exchange!C44 -> 3780 | D12: =Exchange!D44 -> 14580 | E12: =Exchange!E44 -> 36000 | F12: =Exchange!F44 -> 66000
A13: Partner plans for gig posters (PROPOSED) | B13: =Exchange!B45 -> 4740 | C13: =Exchange!C45 -> 18960 | D13: =Exchange!D45 -> 56880 | E13: =Exchange!E45 -> 142200 | F13: =Exchange!F45 -> 284400
A14: TOTAL PLATFORM REVENUE | B14: =SUM(B6:B13) -> 36171.845 | C14: =SUM(C6:C13) -> 146335.46 | D14: =SUM(D6:D13) -> 461472.52 | E14: =SUM(E6:E13) -> 1063406.8 | F14: =SUM(F6:F13) -> 2110654.1
A15: of which The Garden (track A) | B15: =Garden!B33 -> 26229.871 | C15: =Garden!C33 -> 71059.632 | D15: =Garden!D33 -> 157629.22 | E15: =Garden!E33 -> 262808.75 | F15: =Garden!F33 -> 380978.34
A16: of which The Exchange (track B) | B16: =Exchange!B46 -> 9941.9744 | C16: =Exchange!C46 -> 75275.827 | D16: =Exchange!D46 -> 303843.31 | E16: =Exchange!E46 -> 800598.08 | F16: =Exchange!F46 -> 1729675.8
A17: share from PROPOSED lines (plans, event fees) | B17: =IF(B14=0,0,(B10+B12+B13)/B14) -> 0.17527444 | C17: =IF(C14=0,0,(C10+C12+C13)/C14) -> 0.17248041 | D17: =IF(D14=0,0,(D10+D12+D13)/D14) -> 0.16677049 | E17: =IF(E14=0,0,(E10+E12+E13)/E14) -> 0.17815383 | F17: =IF(F14=0,0,(F10+F12+F13)/F14) -> 0.17549062
A19: Scale
A20: Total money moved (GMV, both tracks) | B20: =Garden!B24+Exchange!B35 -> 153919.49 | C20: =Garden!C24+Exchange!C35 -> 767617.54 | D20: =Garden!D24+Exchange!D35 -> 2847551.5 | E20: =Garden!E24+Exchange!E35 -> 7178898.3 | F20: =Garden!F24+Exchange!F35 -> 15341114
A21: Paying and covered members, all communities | B21: =Garden!B6+Garden!B7+Exchange!B23+Exchange!B8 -> 360 | C21: =Garden!C6+Garden!C7+Exchange!C23+Exchange!C8 -> 1980 | D21: =Garden!D6+Garden!D7+Exchange!D23+Exchange!D8 -> 7620 | E21: =Garden!E6+Garden!E7+Exchange!E23+Exchange!E8 -> 17600 | F21: =Garden!F6+Garden!F7+Exchange!F23+Exchange!F8 -> 35400
A22: Paying individuals (Garden members + partner-community members) | B22: =Garden!B6+Exchange!B23 -> 310 | C22: =Garden!C6+Exchange!C23 -> 1480 | D22: =Garden!D6+Exchange!D23 -> 5120 | E22: =Garden!E6+Exchange!E23 -> 13200 | F22: =Garden!F6+Exchange!F23 -> 28000 | G22: founder minimum is 3,000 by year three
A23: Seats bought by organizations (church-covered + org seat packs) | B23: =Garden!B7+Exchange!B8 -> 50 | C23: =Garden!C7+Exchange!C8 -> 500 | D23: =Garden!D7+Exchange!D8 -> 2500 | E23: =Garden!E7+Exchange!E8 -> 4400 | F23: =Garden!F7+Exchange!F8 -> 7400
A24: Revenue from organization-bought seats (seat fees + fees on what those holders buy) | B24: =Garden!B18*Inputs!$B$9+Exchange!B27*Inputs!$B$10+Garden!B7*(Garden!B9*Inputs!$B$11+Garden!B10*Inputs!$B$12)+Exchange!B8*Exchange!B10*Inputs!$B$11 -> 3175 | C24: =Garden!C18*Inputs!$B$9+Exchange!C27*Inputs!$B$10+Garden!C7*(Garden!C9*Inputs!$B$11+Garden!C10*Inputs!$B$12)+Exchange!C8*Exchange!C10*Inputs!$B$11 -> 19000 | D24: =Garden!D18*Inputs!$B$9+Exchange!D27*Inputs!$B$10+Garden!D7*(Garden!D9*Inputs!$B$11+Garden!D10*Inputs!$B$12)+Exchange!D8*Exchange!D10*Inputs!$B$11 -> 76250 | E24: =Garden!E18*Inputs!$B$9+Exchange!E27*Inputs!$B$10+Garden!E7*(Garden!E9*Inputs!$B$11+Garden!E10*Inputs!$B$12)+Exchange!E8*Exchange!E10*Inputs!$B$11 -> 146300 | F24: =Garden!F18*Inputs!$B$9+Exchange!F27*Inputs!$B$10+Garden!F7*(Garden!F9*Inputs!$B$11+Garden!F10*Inputs!$B$12)+Exchange!F8*Exchange!F10*Inputs!$B$11 -> 258100 | G24: house share of church seat packs, 10% of org seat packs, plus 10% of the backings and classes those seat holders buy
A25: share of platform revenue | B25: =IF(B14=0,0,B24/B14) -> 0.08777545 | C25: =IF(C14=0,0,C24/C14) -> 0.12983866 | D25: =IF(D14=0,0,D24/D14) -> 0.16523194 | E25: =IF(E14=0,0,E24/E14) -> 0.1375767 | F25: =IF(F14=0,0,F24/F14) -> 0.12228437
A26: Communities (Garden + partners incl. metros) | B26: =1+Exchange!B22 -> 5 | C26: =1+Exchange!C22 -> 19 | D26: =1+Exchange!D22 -> 55 | E26: =1+Exchange!E22 -> 121 | F26: =1+Exchange!F22 -> 221
A27: Franchise metros active | B27: =Exchange!B20 -> 0 | C27: =Exchange!C20 -> 2 | D27: =Exchange!D20 -> 6 | E27: =Exchange!E20 -> 12 | F27: =Exchange!F20 -> 20
A28: Dollars to creatives, hosts and programs (impact) | B28: =Garden!B19*(1-Inputs!$B$11)+Garden!B20*(1-Inputs!$B$12)+Garden!B38+Exchange!B50+Exchange!B51 -> 81369.871 | C28: =Garden!C19*(1-Inputs!$B$11)+Garden!C20*(1-Inputs!$B$12)+Garden!C38+Exchange!C50+Exchange!C51 -> 433919.63 | D28: =Garden!D19*(1-Inputs!$B$11)+Garden!D20*(1-Inputs!$B$12)+Garden!D38+Exchange!D50+Exchange!D51 -> 1657129.2 | E28: =Garden!E19*(1-Inputs!$B$11)+Garden!E20*(1-Inputs!$B$12)+Garden!E38+Exchange!E50+Exchange!E51 -> 4359658.8 | F28: =Garden!F19*(1-Inputs!$B$11)+Garden!F20*(1-Inputs!$B$12)+Garden!F38+Exchange!F50+Exchange!F51 -> 9619378.3 | G28: what the impact report counts
A29: Platform revenue per paying/covered member per year | B29: =IF(B21=0,0,B14/B21) -> 100.47735 | C29: =IF(C21=0,0,C14/C21) -> 73.906798 | D29: =IF(D21=0,0,D14/D21) -> 60.560699 | E29: =IF(E21=0,0,E14/E21) -> 60.420843 | F29: =IF(F21=0,0,F14/F21) -> 59.622998
A30: Effective take rate (revenue / GMV) | B30: =IF(B20=0,0,B14/B20) -> 0.23500498 | C30: =IF(C20=0,0,C14/C20) -> 0.1906359 | D30: =IF(D20=0,0,D14/D20) -> 0.16205941 | E30: =IF(E20=0,0,E14/E20) -> 0.14812953 | F30: =IF(F20=0,0,F14/F20) -> 0.13758154
A32: Costs by function (salaries carry the payroll load; founders before employees)
A33: Programs & community: founder 2 (Haley) salary + load | B33: =Inputs!$C$159*(1+Inputs!$C$164) -> 57120 | C33: =Inputs!$D$159*(1+Inputs!$D$164) -> 89700 | D33: =Inputs!$E$159*(1+Inputs!$E$164) -> 123900 | E33: =Inputs!$F$159*(1+Inputs!$F$164) -> 150000 | F33: =Inputs!$G$159*(1+Inputs!$G$164) -> 168000
A34: Programs & community: staff salaries + load | B34: =Inputs!$C$174*Inputs!$B$23*(1+Inputs!$C$164) -> 0 | C34: =Inputs!$D$174*Inputs!$B$23*(1+Inputs!$D$164) -> 37375 | D34: =Inputs!$E$174*Inputs!$B$23*(1+Inputs!$E$164) -> 76700 | E34: =Inputs!$F$174*Inputs!$B$23*(1+Inputs!$F$164) -> 78000 | F34: =Inputs!$G$174*Inputs!$B$23*(1+Inputs!$G$164) -> 78000
A35: Programs & community: coordinator hours (Garden) | B35: =Garden!B42 -> 15600 | C35: =Garden!C42 -> 23400 | D35: =Garden!D42 -> 16120 | E35: =Garden!E42 -> 0 | F35: =Garden!F42 -> 0
A36: Programs & community: gathering stipends, venues | B36: =Inputs!$C$200 -> 8000 | C36: =Inputs!$D$200 -> 15000 | D36: =Inputs!$E$200 -> 25000 | E36: =Inputs!$F$200 -> 40000 | F36: =Inputs!$G$200 -> 60000
A37: Programs & community: fellowship program administration | B37: =Inputs!$C$205 -> 2000 | C37: =Inputs!$D$205 -> 5000 | D37: =Inputs!$E$205 -> 10000 | E37: =Inputs!$F$205 -> 15000 | F37: =Inputs!$G$205 -> 20000
A38: PROGRAMS & COMMUNITY | B38: =SUM(B33:B37) -> 82720 | C38: =SUM(C33:C37) -> 170475 | D38: =SUM(D33:D37) -> 251720 | E38: =SUM(E33:E37) -> 283000 | F38: =SUM(F33:F37) -> 326000
A39: Marketing: founder 1 (Rick) sales and partnerships share, salary + load | B39: =Inputs!$C$154*(1+Inputs!$C$164)*Inputs!$C$169 -> 28560 | C39: =Inputs!$D$154*(1+Inputs!$D$164)*Inputs!$D$169 -> 44850 | D39: =Inputs!$E$154*(1+Inputs!$E$164)*Inputs!$E$169 -> 61950 | E39: =Inputs!$F$154*(1+Inputs!$F$164)*Inputs!$F$169 -> 75000 | F39: =Inputs!$G$154*(1+Inputs!$G$164)*Inputs!$G$169 -> 84000
A40: Marketing: staff salaries + load | B40: =Inputs!$C$184*Inputs!$B$25*(1+Inputs!$C$164) -> 21000 | C40: =Inputs!$D$184*Inputs!$B$25*(1+Inputs!$D$164) -> 43125 | D40: =Inputs!$E$184*Inputs!$B$25*(1+Inputs!$E$164) -> 88500 | E40: =Inputs!$F$184*Inputs!$B$25*(1+Inputs!$F$164) -> 90000 | F40: =Inputs!$G$184*Inputs!$B$25*(1+Inputs!$G$164) -> 90000
A41: Marketing: launch and annual events | B41: =Inputs!$C$216 -> 12000 | C41: =Inputs!$D$216 -> 18000 | D41: =Inputs!$E$216 -> 25000 | E41: =Inputs!$F$216 -> 35000 | F41: =Inputs!$G$216 -> 45000
A42: Marketing: film and story production | B42: =Inputs!$C$221 -> 10000 | C42: =Inputs!$D$221 -> 12000 | D42: =Inputs!$E$221 -> 15000 | E42: =Inputs!$F$221 -> 20000 | F42: =Inputs!$G$221 -> 20000
A43: Marketing: content, design, outreach | B43: =Inputs!$C$226 -> 5000 | C43: =Inputs!$D$226 -> 15000 | D43: =Inputs!$E$226 -> 35000 | E43: =Inputs!$F$226 -> 60000 | F43: =Inputs!$G$226 -> 90000
...

Sheet Market
A1: Market — who is out there, and what share the model assumes
A2: Blue cells are to be confirmed against the market-sizing research (docs/funding/market-sizing.md). Sources in column C.
A4: Counts
A5: San Diego MSA: arts, design, entertainment, sports & media occupations (BLS OEWS 27-0000), wage-and-salary jobs | B5: 19990 | C5: BLS OEWS May 2025, San Diego-Chula Vista-Carlsbad MSA (area 41740). Includes 2,890 coaches/scouts and 2,730 PR specialists. market-sizing.md §1
A6: San Diego County: creatives outside payroll data (gap to the 26,000 central estimate) | B6: 6010 | C6: Central estimate 26,000 working creatives = NEA artist share × county labor force, scaled by SD location quotient (range 22,000–30,000). Lightcast counts 43,968 self-employed creative-economy JOBS (2022), incl. side income. ESTIMATE
A7: San Diego County working creatives (best estimate) | B7: =B5+B6 -> 26000 | C7: sum; the 'any paid creative activity' pool is plausibly 45,000+
A8: San Diego County congregations | B8: 1555 | C8: ARDA 2020 US Religion Census, San Diego County, 94 bodies reporting (undercounts nondenominational and Black church bodies)
A9: Church-based creatives in the county (worship, media, design volunteers), estimate | B9: 4000 | C9: 1,555 × 35–46% of congregations with a band or projection (NCS-IV 2018-19) × 4–8 volunteers; range 2,200–5,700. ASSUMPTION
A10: California arts, design, entertainment & media occupations (BLS OEWS 27-0000) | B10: 338230 | C10: BLS OEWS May 2025, California. Otis College counts ~734,000 creative-economy jobs (industry-based, Apr 2026)
A11: US artists and cultural workers in the labor force (NEA) | B11: 3800000 | C11: NEA Artists in the Workforce, Sep 2025: 2.7M artists + 1.1M other cultural workers (CPS 2024)
A12: US congregations | B12: 373000 | C12: Hartford Institute estimate (range 356,642 US Religion Census to 384,000 Brauer)
A13: US church-based creatives, estimate | B13: 950000 | C13: 373,000 × 35–46% × 4–8 volunteers = 0.53M–1.37M; midpoint. ASSUMPTION
A14: Members of Christian creative networks already mapped (Hope*Writers, Word Weavers, Realm Makers, ACFW, Rabbit Room, Anselm, Makers & Mystics…) | B14: 9200 | C14: Documented ~4,600 (Hope*Writers 3,200, Word Weavers 900, Realm Makers 500; all secondary) × 2 for networks that publish no counts; range 4,600–13,800. ESTIMATE
A15: Overlap between the three SAM segments (haircut) | B15: 0.1 | C15: ASSUMPTION
A16: Three-year members incl. schools, churches and other organizations: low (founder estimate) | B16: 5000 | C16: Founder estimate 2026-09-30, NOT sourced. Individuals alone benchmark to about 1,000 (market-sizing.md); the rest is seats bought by schools and organizations. Source a count of San Diego schools, universities and organizations to firm this up
A17: Three-year members incl. schools, churches and other organizations: high (founder estimate) | B17: 10000 | C17: Founder estimate 2026-09-30, NOT sourced
A18: Paying individuals in three years, minimum (founder) | B18: 3000 | C18: Founder 2026-09-30: individuals need to be at least 3,000 by year three. The individual-conversion benchmark supports about 1,000 for San Diego alone, so this needs partner communities outside San Diego (Base has 30 by year three)
A20: The ladder
A21: TAM — US working creatives + church-based creatives | B21: =B11+B13 -> 4750000 | C21: people who could hold a seat
A22: SAM — San Diego creatives + church creatives + mapped networks, less overlap | B22: =(B7+B9+B14)*(1-B15) -> 35280 | C22: reachable in three years through partners we already know; research range 26,000–45,000 (market-sizing.md §6)
A23: Penetration of SAM | B23: Paying members
A24: 0.01 | B24: =A24*B22 -> 352.8
A25: 0.02 | B25: =A25*B22 -> 705.6
A26: 0.03 | B26: =A26*B22 -> 1058.4
A27: 0.05 | B27: =A27*B22 -> 1764
A28: 0.1 | B28: =A28*B22 -> 3528
A30: What the active scenario assumes
A31: Paying and covered members, Y3 (Combined) | B31: =Combined!D21 -> 7620
A32: as a share of SAM | B32: =B31/B22 -> 0.21598639 | C32: Hope*Writers alone holds ~3,200 paying members; 2–3% of SAM by Y3 is the Base case
A33: Paying and covered members, Y5 (Combined) | B33: =Combined!F21 -> 35400
A34: as a share of SAM | B34: =B33/B22 -> 1.0034014
A35: Garden members Y3 as a share of San Diego creatives + church creatives | B35: =(Garden!D6+Garden!D7)/(B7+B9) -> 0.043333333 | C35: the local sanity check
A36: Active scenario Y3 members vs the founder-estimated range (5,000 to 10,000) | B36: =IF(Combined!D21<B16,"below",IF(Combined!D21>B17,"above","inside")) -> inside | C36: Base should sit inside the range; Conservative below it (individuals only); Fundable at or above the top
A37: Active scenario Y3 paying individuals vs the 3,000 minimum | B37: =IF(Combined!D22>=B18,"meets","below") -> meets | C37: Base meets it (about 3,200); Conservative is below (about 950, the individual-conversion benchmark)
A38: Paying and covered members, Y5, as a share of US TAM | B38: =Combined!F21/B21 -> 0.0074526316 | C38: the national sanity check: partner communities and org seats are not confined to San Diego from Y2 on

Sheet Use of Funds
A1: Use of Funds — what the raise buys, and how long it lasts (active scenario)
A2: Blue = edit. The budget window is Y1 plus a share of Y2 (months over 12). Functional totals include salaries with payroll load; founders are in Programs (Haley) and Engineering (Rick).
A4: Raise amount, $ | B4: 350000
A5: Months the raise must cover | B5: 18
A6: Share of Y1 in the window | B6: =MIN(B5,12)/12 -> 1
A7: Share of Y2 in the window | B7: =MAX(0,B5-12)/12 -> 0.5
A9: Budget for the window, by function
A10: Function | B10: Window $ | C10: Share | D10: Y1 | E10: Y2 | F10: Y3 | G10: Y4 | H10: Note
A11: Programs & community (incl. founder 2) | B11: =Combined!B38*$B$6+Combined!C38*$B$7 -> 167957.5 | C11: =IF(B17=0,0,B11/B17) -> 0.3669766 | D11: =Combined!B38 -> 82720 | E11: =Combined!C38 -> 170475 | F11: =Combined!D38 -> 251720 | G11: =Combined!E38 -> 283000 | H11: community lead hire, coordinator hours, gathering stipends, program administration
A12: Marketing & launch (incl. founder 1 business half) | B12: =Combined!B46*$B$6+Combined!C46*$B$7 -> 166047.5 | C12: =IF(B17=0,0,B12/B17) -> 0.36280337 | D12: =Combined!B46 -> 78560 | E12: =Combined!C46 -> 174975 | F12: =Combined!D46 -> 321450 | G12: =Combined!E46 -> 444000 | H12: Rick's sales and partnerships half, part-time launch help, 2027 launches, film series, content, metro launches, travel
A13: Support | B13: =Combined!B49*$B$6+Combined!C49*$B$7 -> 5000 | C13: =IF(B17=0,0,B13/B17) -> 0.010924686 | D13: =Combined!B49 -> 2000 | E13: =Combined!C49 -> 6000 | F13: =Combined!D49 -> 8000 | G13: =Combined!E49 -> 10000 | H13: part-time coverage, then a support hire
A14: Engineering & platform (incl. founder 1) | B14: =Combined!B55*$B$6+Combined!C55*$B$7 -> 75485 | C14: =IF(B17=0,0,B14/B17) -> 0.16492999 | D14: =Combined!B55 -> 41060 | E14: =Combined!C55 -> 68850 | F14: =Combined!D55 -> 107950 | G14: =Combined!E55 -> 144000 | H14: hosting, contractors, payments compliance; founder is the engineering team until Y3
A15: Operations & G&A | B15: =Combined!B61*$B$6+Combined!C61*$B$7 -> 34500 | C15: =IF(B17=0,0,B15/B17) -> 0.075380335 | D15: =Combined!B61 -> 21500 | E15: =Combined!C61 -> 26000 | F15: =Combined!D61 -> 42000 | G15: =Combined!E61 -> 60000 | H15: legal (entity, agreements), accounting, insurance, admin
A16: Payments (cost of money moved) | B16: =Combined!B63*$B$6+Combined!C63*$B$7 -> 8689.0479 | C16: =IF(B17=0,0,B16/B17) -> 0.018985024 | D16: =Combined!B63 -> 2325.7135 | E16: =Combined!C63 -> 12726.669 | F16: =Combined!D63 -> 48205.799 | G16: =Combined!E63 -> 125747.65 | H16: card processing absorbed and payout costs
A17: TOTAL SPEND IN THE WINDOW | B17: =SUM(B11:B16) -> 457679.05 | D17: =SUM(D11:D16) -> 228165.71 | E17: =SUM(E11:E16) -> 459026.67 | F17: =SUM(F11:F16) -> 779325.8 | G17: =SUM(G11:G16) -> 1066747.6
A18: of which founders (both, loaded) | B18: =Combined!B67*$B$6+Combined!C67*$B$7 -> 203940 | C18: =IF(B17=0,0,B18/B17) -> 0.4455961 | D18: =Combined!B67 -> 114240 | E18: =Combined!C67 -> 179400 | F18: =Combined!D67 -> 247800 | G18: =Combined!E67 -> 300000
A19: founder 2 (Haley), loaded, inside Programs & community | B19: =Combined!B33*$B$6+Combined!C33*$B$7 -> 101970 | D19: =Combined!B33 -> 57120 | E19: =Combined!C33 -> 89700 | F19: =Combined!D33 -> 123900 | G19: =Combined!E33 -> 150000
A20: founder 1 (Rick), loaded, product half inside Engineering & platform | B20: =Combined!B50*$B$6+Combined!C50*$B$7 -> 50985 | D20: =Combined!B50 -> 28560 | E20: =Combined!C50 -> 44850 | F20: =Combined!D50 -> 61950 | G20: =Combined!E50 -> 75000
A21: founder 1 (Rick), loaded, business half inside Marketing & launch | B21: =Combined!B39*$B$6+Combined!C39*$B$7 -> 50985 | D21: =Combined!B39 -> 28560 | E21: =Combined!C39 -> 44850 | F21: =Combined!D39 -> 61950 | G21: =Combined!E39 -> 75000
A22: of which all people (founders + staff, loaded) | B22: =Combined!B66*$B$6+Combined!C66*$B$7 -> 265190 | C22: =IF(B17=0,0,B22/B17) -> 0.57942351 | D22: =Combined!B66 -> 135240 | E22: =Combined!C66 -> 259900 | F22: =Combined!D66 -> 413000 | G22: =Combined!E66 -> 468000
A24: Platform revenue in the window | B24: =Combined!B14*$B$6+Combined!C14*$B$7 -> 109339.57 | D24: =Combined!B14 -> 36171.845 | E24: =Combined!C14 -> 146335.46 | F24: =Combined!D14 -> 461472.52 | G24: =Combined!E14 -> 1063406.8
A25: NET CASH NEED IN THE WINDOW (spend less revenue) | B25: =B17-B24 -> 348339.47
A26: Raise less net need (cushion) | B26: =B4-B25 -> 1660.5271 | C26: =IF(B25=0,0,B26/B25) -> 0.0047669795 | H26: negative = the raise does not cover the window
A28: Headcount plan (FTE by year; founders first, then hires gated on revenue)
A29: Role | D29: Y1 | E29: Y2 | F29: Y3 | G29: Y4 | H29: Y5
A30: Founders (Rick: product & engineering; Haley: community & programs) | D30: 2 | E30: 2 | F30: 2 | G30: 2 | H30: 2
A31: Community & partnerships | D31: =Inputs!$C$174 -> 0 | E31: =Inputs!$D$174 -> 0.5 | F31: =Inputs!$E$174 -> 1 | G31: =Inputs!$F$174 -> 1 | H31: =Inputs!$G$174 -> 1
A32: Member support | D32: =Inputs!$C$179 -> 0 | E32: =Inputs!$D$179 -> 0 | F32: =Inputs!$E$179 -> 0 | G32: =Inputs!$F$179 -> 0 | H32: =Inputs!$G$179 -> 0
A33: Marketing | D33: =Inputs!$C$184 -> 0.25 | E33: =Inputs!$D$184 -> 0.5 | F33: =Inputs!$E$184 -> 1 | G33: =Inputs!$F$184 -> 1 | H33: =Inputs!$G$184 -> 1
A34: Engineering | D34: =Inputs!$C$189 -> 0 | E34: =Inputs!$D$189 -> 0 | F34: =Inputs!$E$189 -> 0 | G34: =Inputs!$F$189 -> 0 | H34: =Inputs!$G$189 -> 0
A35: Operations / finance | D35: =Inputs!$C$194 -> 0 | E35: =Inputs!$D$194 -> 0 | F35: =Inputs!$E$194 -> 0 | G35: =Inputs!$F$194 -> 0 | H35: =Inputs!$G$194 -> 0
A36: TOTAL FTE | D36: =SUM(D30:D35) -> 2.25 | E36: =SUM(E30:E35) -> 3 | F36: =SUM(F30:F35) -> 4 | G36: =SUM(G30:G35) -> 4 | H36: =SUM(H30:H35) -> 4
A37: Revenue per FTE | D37: =IF(D36=0,0,Combined!B14/D36) -> 16076.376 | E37: =IF(E36=0,0,Combined!C14/E36) -> 48778.486 | F37: =IF(F36=0,0,Combined!D14/F36) -> 115368.13 | G37: =IF(G36=0,0,Combined!E14/G36) -> 265851.71 | H37: =IF(H36=0,0,Combined!F14/H36) -> 527663.53
A38: Founder pay, each (cash paid in the year) | D38: =Inputs!$C$154 -> 51000 | E38: =Inputs!$D$154 -> 78000 | F38: =Inputs!$E$154 -> 105000 | G38: =Inputs!$F$154 -> 125000 | H38: conditional on a first close of at least $150k; starts the month after, on a ramp
A40: Runway by raise size (active scenario; burn = costs less revenue, spent evenly within each year)
A41: Net burn by year | B41: =MAX(0,Combined!B65-Combined!B14) -> 191993.87 | C41: =MAX(0,Combined!C65-Combined!C14) -> 312691.21 | D41: =MAX(0,Combined!D65-Combined!D14) -> 317853.27 | E41: =MAX(0,Combined!E65-Combined!E14) -> 3340.8155 | F41: =MAX(0,Combined!F65-Combined!F14) -> 0
A42: Monthly burn by year | B42: =B41/12 -> 15999.489 | C42: =C41/12 -> 26057.601 | D42: =D41/12 -> 26487.773 | E42: =E41/12 -> 278.40129 | F42: =F41/12 -> 0
A44: Raise, $ | B44: Runway, months | C44: Note
A45: 150000 | B45: =MIN(60,IF(A45<=$B$41,A45/MAX(1,$B$41/12),IF(A45<=$B$41+$C$41,12+(A45-$B$41)/MAX(1,$C$41/12),IF(A45<=$B$41+$C$41+$D$41,24+(A45-$B$41-$C$41)/MAX(1,$D$41/12),IF(A45<=$B$41+$C$41+$D$41+$E$41,36+(A45-$B$41-$C$41-$D$41)/MAX(1,$E$41/12),IF(A45<=$B$41+$C$41+$D$41+$E$41+$F$41,48+(A45-$B$41-$C$41-$D$41-$E$41)/MAX(1,$F$41/12),60)))))) -> 9.3752994 | C45: 60 = the raise outlasts the five-year model
A46: 250000 | B46: =MIN(60,IF(A46<=$B$41,A46/MAX(1,$B$41/12),IF(A46<=$B$41+$C$41,12+(A46-$B$41)/MAX(1,$C$41/12),IF(A46<=$B$41+$C$41+$D$41,24+(A46-$B$41-$C$41)/MAX(1,$D$41/12),IF(A46<=$B$41+$C$41+$D$41+$E$41,36+(A46-$B$41-$C$41-$D$41)/MAX(1,$E$41/12),IF(A46<=$B$41+$C$41+$D$41+$E$41+$F$41,48+(A46-$B$41-$C$41-$D$41-$E$41)/MAX(1,$F$41/12),60)))))) -> 14.226073 | C46: 60 = the raise outlasts the five-year model
...

Sheet Sensitivity
A1: Sensitivity — Y3 platform revenue = paying/covered members × revenue per member
A2: Rows: members. Columns: revenue per member per year (Combined!D shows the active scenario's actual). Black = formula.
A4: Active scenario Y3 members | B4: =Combined!D21 -> 7620
A5: Active scenario Y3 revenue per member | B5: =Combined!D29 -> 60.560699
A6: Active scenario Y3 costs | B6: =Combined!D65 -> 779325.8
A8: Members \ $ per member | B8: 20 | C8: 40 | D8: 60 | E8: 90 | F8: 120 | G8: 160 | H8: 200
A9: 1000 | B9: =$A9*B$8 -> 20000 | C9: =$A9*C$8 -> 40000 | D9: =$A9*D$8 -> 60000 | E9: =$A9*E$8 -> 90000 | F9: =$A9*F$8 -> 120000 | G9: =$A9*G$8 -> 160000 | H9: =$A9*H$8 -> 200000
A10: 2500 | B10: =$A10*B$8 -> 50000 | C10: =$A10*C$8 -> 100000 | D10: =$A10*D$8 -> 150000 | E10: =$A10*E$8 -> 225000 | F10: =$A10*F$8 -> 300000 | G10: =$A10*G$8 -> 400000 | H10: =$A10*H$8 -> 500000
A11: 5000 | B11: =$A11*B$8 -> 100000 | C11: =$A11*C$8 -> 200000 | D11: =$A11*D$8 -> 300000 | E11: =$A11*E$8 -> 450000 | F11: =$A11*F$8 -> 600000 | G11: =$A11*G$8 -> 800000 | H11: =$A11*H$8 -> 1000000
A12: 10000 | B12: =$A12*B$8 -> 200000 | C12: =$A12*C$8 -> 400000 | D12: =$A12*D$8 -> 600000 | E12: =$A12*E$8 -> 900000 | F12: =$A12*F$8 -> 1200000 | G12: =$A12*G$8 -> 1600000 | H12: =$A12*H$8 -> 2000000
A13: 20000 | B13: =$A13*B$8 -> 400000 | C13: =$A13*C$8 -> 800000 | D13: =$A13*D$8 -> 1200000 | E13: =$A13*E$8 -> 1800000 | F13: =$A13*F$8 -> 2400000 | G13: =$A13*G$8 -> 3200000 | H13: =$A13*H$8 -> 4000000
A14: 40000 | B14: =$A14*B$8 -> 800000 | C14: =$A14*C$8 -> 1600000 | D14: =$A14*D$8 -> 2400000 | E14: =$A14*E$8 -> 3600000 | F14: =$A14*F$8 -> 4800000 | G14: =$A14*G$8 -> 6400000 | H14: =$A14*H$8 -> 8000000
A16: Read: at $60 per member the platform needs about 5,000 paying or covered members to cover $300k of costs; at $120 it needs 2,500. The old model sat near $22–30 per member; B2B seats, plans and event fees are what lift it.

Sheet Comps
A1: Comps — what others charge and what they reach
A3: Platform | B3: Price / take | C3: Scale | D3: Source (verify before quoting)
A4: Skool | B4: $99/mo per community (or $9/mo + 10%), 2.9% processing | C4: 170k+ communities claimed ⚠ | D4: skool.com/pricing; partner-landscape.md §4
A5: Circle | B5: $89–$219/mo per community + 1–2% | C5: — | D5: circle.so/pricing
A6: Mighty Networks | B6: $79–$179/mo per community + 1–2% | C6: — | D6: mightynetworks.com/pricing
A7: Patreon | B7: 10% of creator earnings (new creators) + processing | C7: $8B+ paid out to creators over 13 years ⚠ | D7: patreon.com/pricing; partner-landscape.md §4
A8: Substack | B8: 10% + processing | C8: ~35k+ paying writers ⚠ | D8: substack.com
A9: Kickstarter | B9: 5% + 3–5% processing | C9: creative-category pledges | D9: kickstarter.com/help
A10: Eventbrite | B10: 3.7% + $1.79 per paid ticket | C10: — | D10: eventbrite.com/organizer/pricing
A11: Hope*Writers | B11: $47/mo membership | C11: 3,200+ paying members ⚠ (~$1.8M/yr) | D11: partner-landscape.md §6a
A12: ACFW | B12: $75 join + $49/yr | C12: ~3,000 members, 31 chapters | D12: partner-landscape.md §6a
A13: Word Weavers | B13: $55/yr | C13: 1,200 writers, 30+ chapters, $212k/yr budget | D13: partner-landscape.md §6a
A14: Realm Makers | B14: $7.99–$11.99/mo (Mighty Networks) | C14: 350 at conference + online | D14: partner-landscape.md §6a
A15: theCreative.exchange (this model) | B15: $10/mo seat; 10% of backings and classes; 5% on gifts; PROPOSED $50 host plan, $79 partner plan, 5% tickets | C15: Combined sheet | D15: claims.md; Business Model
